<robot name="obstacle_car" xmlns:xacro="http://www.ros.org/wiki/xacro">
    <!-- Defining the colors used in this robot  -->
   <material name="Black">
        <color rgba="0 0 0 1" />
    </material>

    <material name="White">
        <color rgba="1 1 1 1" />
    </material>

    <material name="Blue">
        <color rgba="0 0 1 1" />
    </material>

    <material name="Red">
        <color rgba="1 0 0 1" />
    </material>

    <material name="Brown">
        <color rgba="0.647 0.165 0.165 1" />
    </material> 

     <xacro:property name="PI" value="3.1415926"/> 
	<xacro:property name="length_wheel" value="0.05" />
	<xacro:property name="radius_wheel" value="0.06" /> 

    <!-- Inertial matrix  -->
     <xacro:macro name="inertial_matrix" params="mass">
        <inertial>
            <mass value="${mass}" />
            <origin xyz="0 0 0" rpy="0 0 0" />
            <inertia ixx="0.01" ixy="0.0" ixz="0.0" iyy="0.01" iyz="0.0" izz="0.01" />
        </inertial>
    </xacro:macro>

<xacro:macro name="Box_inertial_matrix" params="m l w h">
       <inertial>
               <mass value="${m}" />
               <inertia ixx="${m*(h*h + l*l)/12}" ixy = "0" ixz = "0"
                   iyy="${m*(w*w + l*l)/12}" iyz= "0"
                   izz="${m*(w*w + h*h)/12}" />
       </inertial>
    </xacro:macro>
    
    <!-- Defining the inertial matrix used for cylinder -->
    <xacro:macro name="cylinder_inertial_matrix" params="m r h">
        <inertial>
            <mass value="${m}" />
            <inertia ixx="${m*(3*r*r+h*h)/12}" ixy = "0" ixz = "0"
                iyy="${m*(3*r*r+h*h)/12}" iyz = "0"
                izz="${m*r*r/2}" /> 
        </inertial>
    </xacro:macro>
    <xacro:macro name="gazebo_material" params="ref color">
        <gazebo reference="${ref}">
            <pose>0 0 0 0 0 0</pose>
            <material>Gazebo/${color}</material>
        </gazebo>
    </xacro:macro> 

    <!-- //////////////////////////////// all base links of sentry ////////////////////////////////// -->
    <link name="obstacle_dummy" />
        <visual>
            <origin xyz=" 5 0 0" rpy="0 0 0"/>
        </visual>
    <link name="obstacle_base_footprint">
        <visual>
            <origin xyz="0 0 0" rpy="0 0 0" />
            <geometry>
                <box size="0.001 0.001 0.001" />
            </geometry>
            <material name="Blue" />
        </visual>
        <collision>
            <origin xyz="0 0 0" rpy="0 0 0" />
            <geometry>
                <box size="0.1 0.1 0.1" />
            </geometry>
        </collision>
        <xacro:inertial_matrix mass="10"/>
    </link>

    <link name="obstacle_base_link">
        <visual>
            <origin xyz="0 0 0.05" rpy="0 0 0"/>
            <geometry>
                <box size="0.5 0.5 0.4"/>
            </geometry>
            <material name="White" />
        </visual>
        <collision>
            <origin xyz="0 0 0.05" rpy="0 0 0"/>
            <geometry>
                <box size="0.5 0.5 0.4"/>
            </geometry>
        </collision>
        <xacro:Box_inertial_matrix m="25" l="0.5" w="0.5" h="0.4"/>
    </link>

    <link name="obstacle_left_front_wheel">
        <visual>
            <origin xyz="0 0 0" rpy="0 0 0" />
            <geometry>
                <cylinder radius="${radius_wheel}" length="${length_wheel}" />
            </geometry>
            <material name="Black" />
        </visual>
        <collision>
            <origin xyz="0 0 0" rpy="0 0 0" />
            <geometry>
                <cylinder radius="${radius_wheel}" length="${length_wheel}" />
            </geometry>
        </collision>
        <xacro:cylinder_inertial_matrix m="0.5" r="${radius_wheel}" h="${length_wheel}"/>
    </link>

    <link name="obstacle_right_front_wheel">
        <visual>
            <origin xyz="0 0 0" rpy="0 0 0" />
            <geometry>
                <cylinder radius="${radius_wheel}" length="${length_wheel}" />
            </geometry>
            <material name="Black" />
        </visual>
        <collision>
            <origin xyz="0 0 0" rpy="0 0 0" />
            <geometry>
                <cylinder radius="${radius_wheel}" length="${length_wheel}" />
            </geometry>
        </collision>
        <xacro:cylinder_inertial_matrix m="0.5" r="${radius_wheel}" h="${length_wheel}"/>
    </link>

    <link name="obstacle_left_rear_wheel">
        <visual>
            <origin xyz="0 0 0" rpy="0 0 0" />
            <geometry>
                <cylinder radius="${radius_wheel}" length="${length_wheel}" />
            </geometry>
            <material name="Red" />
        </visual>
        <collision>
            <origin xyz="0 0 0" rpy="0 0 0" />
            <geometry>
                <cylinder radius="${radius_wheel}" length="${length_wheel}" />
            </geometry>
        </collision>
        <xacro:cylinder_inertial_matrix m="0.5" r="${radius_wheel}" h="${length_wheel}"/>
    </link>

    <link name="obstacle_right_rear_wheel">
        <visual>
            <origin xyz="0 0 0" rpy="0 0 0" />
            <geometry>
                <cylinder radius="${radius_wheel}" length="${length_wheel}" />
            </geometry>
            <material name="Red" />
        </visual>
        <collision>
            <origin xyz="0 0 0" rpy="0 0 0" />
            <geometry>
                <cylinder radius="${radius_wheel}" length="${length_wheel}" />
            </geometry>
        </collision>
        <xacro:cylinder_inertial_matrix m="0.5" r="${radius_wheel}" h="${length_wheel}"/>
    </link>

    <!-- //////////////////////////////// all joints ////////////////////////////////// -->
    <joint name="obstacle_dummy_joint" type="fixed">
        <parent link="obstacle_dummy" />
        <child link="obstacle_base_footprint" />
    </joint>

	<joint name="obstacle_base_footprint_joint" type="fixed">
		<origin xyz="0 0 0" />
		<parent link="obstacle_base_footprint" />
		<child link="obstacle_base_link" />
	</joint>

    <joint name="obstacle_base_to_wheel1" type="continuous">
        <axis xyz="0 0 1" />
        <anchor xyz="0 0 0" />
        <limit effort="100" velocity="100" />
        <parent link="obstacle_base_link"/>
        <child link="obstacle_left_front_wheel"/>
        <origin rpy="${-PI/2} 0 0" xyz="0.1 0.13 0"/>
    </joint>

    <joint name="obstacle_base_to_wheel2" type="continuous">
        <axis xyz="0 0 1" />
        <anchor xyz="0 0 0" />
        <limit effort="100" velocity="100" />
        <parent link="obstacle_base_link"/>
        <child link="obstacle_left_rear_wheel"/>
        <origin rpy="${-PI/2} 0 0" xyz="-0.1 0.13 0"/>
    </joint>

    <joint name="obstacle_base_to_wheel3" type="continuous">
        <axis xyz="0 0 1" />
        <anchor xyz="0 0 0" />
        <limit effort="100" velocity="100" />
        <parent link="obstacle_base_link"/>
        <child link="obstacle_right_front_wheel"/>
        <origin rpy="${-PI/2} 0 0" xyz="0.1 -0.13 0"/>
    </joint>

    <joint name="obstacle_base_to_wheel4" type="continuous">
        <axis xyz="0 0 1" />
        <anchor xyz="0 0 0" />
        <limit effort="100" velocity="100" />
        <parent link="obstacle_base_link"/>
        <child link="obstacle_right_rear_wheel"/>
        <origin rpy="${-PI/2} 0 0" xyz="-0.1 -0.13 0"/>
    </joint>

    <!-- //////////////////////////////// gazebo ////////////////////////////////// -->
    <xacro:gazebo_material ref="obstacle_base_footprint"    color="White" />
    <xacro:gazebo_material ref="obstacle_base_link"         color="Orange" />
    <xacro:gazebo_material ref="obstacle_left_front_wheel"  color="Black" />
    <xacro:gazebo_material ref="obstacle_right_front_wheel" color="Black" />
    <xacro:gazebo_material ref="obstacle_left_rear_wheel"   color="Red" />
    <xacro:gazebo_material ref="obstacle_right_rear_wheel"  color="Red" />   

    <!-- //// ////////////////////////////// driver controller //////////////////////////////////  -->
    <gazebo>
        <plugin name="mecanum_controller" filename="libgazebo_ros_planar_move.so">
            <always_on>true</always_on>
            <updateRate>100.0</updateRate>
            <robotNamespace>/</robotNamespace>
            <commandTopic>obstacle/cmd_vel</commandTopic>
            <odometryTopic>obstacle/odom</odometryTopic>
            <odometryFrame>obstacle/odom</odometryFrame>
            <leftFrontJoint>obstacle_base_to_wheel1</leftFrontJoint>
            <rightFrontJoint>obstacle_base_to_wheel3</rightFrontJoint>
            <leftRearJoint>obstacle_base_to_wheel2</leftRearJoint>
            <rightRearJoint>obstacle_base_to_wheel4</rightRearJoint>
            <wheelSeparation>0.26</wheelSeparation>
            <wheelDiameter>0.12</wheelDiameter>
            <odometryRate>20.0</odometryRate>
            <torque>2</torque>
            <robotBaseFrame>obstacle_base_footprint</robotBaseFrame>
            <publishOdomTF>true</publishOdomTF>
            <broadcastTF>true</broadcastTF>
            <cmdTimeout>1.0</cmdTimeout>
        </plugin>
    </gazebo>

</robot>
